<mujoco model="panda">
    <compiler angle="radian" meshdir="meshes/" />
    <option tolerance="1e-06" collision="predefined" cone="elliptic" jacobian="sparse" solver="CG" iterations="30" />
    <size njmax="500" nconmax="100" />
    <asset>
        <mesh name="link0" file="visual/link0_.stl" />
        <mesh name="link1" file="visual/link1_.stl" />
        <mesh name="link2" file="visual/link2_.stl" />
        <mesh name="link3" file="visual/link3_.stl" />
        <mesh name="link4" file="visual/link4_.stl" />
        <mesh name="link5" file="visual/link5_.stl" />
        <mesh name="link6" file="visual/link6_.stl" />
        <mesh name="link7" file="collision/link7.stl" />
    </asset>
    <worldbody>
        <geom type="mesh" rgba="1 1 1 1" mesh="link0" />
        <body name="panda_link1" pos="0 0 0.333">
            <inertial pos="0 -0.04 -0.05" mass="2.7" diaginertia="0.1 0.1 0.1" />
            <joint name="panda_joint1" pos="0 0 0" axis="0 0 1" limited="true" range="-2.9671 2.9671" />
            <geom type="mesh" rgba="1 1 1 1" mesh="link1" />
            <body name="panda_link2" pos="0 0 0" quat="0.707107 -0.707107 0 0">
                <inertial pos="0 -0.04 0.06" mass="2.73" diaginertia="0.1 0.1 0.1" />
                <joint name="panda_joint2" pos="0 0 0" axis="0 0 1" limited="true" range="-1.8326 1.8326" />
                <geom type="mesh" rgba="1 1 1 1" mesh="link2" />
                <body name="panda_link3" pos="0 -0.316 0" quat="0.707107 0.707107 0 0">
                    <inertial pos="0.01 0.01 -0.05" mass="2.04" diaginertia="0.1 0.1 0.1" />
                    <joint name="panda_joint3" pos="0 0 0" axis="0 0 1" limited="true" range="-2.9671 2.9671" />
                    <geom type="mesh" rgba="1 1 1 1" mesh="link3" />
                    <body name="panda_link4" pos="0.0825 0 0" quat="0.707107 0.707107 0 0">
                        <inertial pos="-0.03 0.03 0.02" mass="2.08" diaginertia="0.1 0.1 0.1" />
                        <joint name="panda_joint4" pos="0 0 0" axis="0 0 1" limited="true" range="-3.1416 0" />
                        <geom type="mesh" rgba="1 1 1 1" mesh="link4" />
                        <body name="panda_link5" pos="-0.0825 0.384 0" quat="0.707107 -0.707107 0 0">
                            <inertial pos="0 0.04 -0.12" mass="3" diaginertia="0.1 0.1 0.1" />
                            <joint name="panda_joint5" pos="0 0 0" axis="0 0 1" limited="true" range="-2.9671 2.9671" />
                            <geom type="mesh" rgba="1 1 1 1" mesh="link5" />
                            <body name="panda_link6" pos="0 0 0" quat="0.707107 0.707107 0 0">
                                <inertial pos="0.04 0 0" mass="1.3" diaginertia="0.1 0.1 0.1" />
                                <joint name="panda_joint6" pos="0 0 0" axis="0 0 1" limited="true" range="-0.0873 3.8223" />
                                <geom type="mesh" rgba="1 1 1 1" mesh="link6" />
                                <body name="panda_link7" pos="0.088 0 0" quat="0.707107 0.707107 0 0">
                                    <inertial pos="0 0 0.08" mass="0.2" diaginertia="0.1 0.1 0.1" />
                                    <joint name="panda_joint7" pos="0 0 0" axis="0 0 1" limited="true" range="-2.9671 2.9671" />
                                    <geom type="mesh" rgba="1 1 1 1" mesh="link7" />
                                </body>
                            </body>
                        </body>
                    </body>
                </body>
            </body>
        </body>
    </worldbody>
    <actuator>
        <!-- <position name="j1" ctrlrange="-2.9671 2.9671" joint="panda_joint2" kp = "300"/>
        <position name="j2" ctrlrange="-1.8326 1.8326" joint="panda_joint3" kp = "300"/>
        <position name="j3" ctrlrange="-2.9671 2.9671" joint="panda_joint4" kp = "300"/>
        <position name="j4" ctrlrange="-3.1416 0" joint="panda_joint2" kp = "300"/>
        <position name="j5" ctrlrange="-2.9671 2.9671" joint="panda_joint5" kp = "300"/>
        <position name="j6" ctrlrange="-0.0873 3.8223" joint="panda_joint6" kp = "300"/>
        <position name="j7" ctrlrange="-2.9671 2.9671" joint="panda_joint7" kp = "300"/> -->

        <!-- Physical limits of the actuator. -->
        <motor ctrllimited="true" ctrlrange="-80.0 80.0" joint="panda_joint1" name="j1"/>
        <motor ctrllimited="true" ctrlrange="-80.0 80.0" joint="panda_joint2" name="j2"/>
        <motor ctrllimited="true" ctrlrange="-80.0 80.0" joint="panda_joint3" name="j3"/>
        <motor ctrllimited="true" ctrlrange="-80.0 80.0" joint="panda_joint4" name="j4"/>
        <motor ctrllimited="true" ctrlrange="-80.0 80.0" joint="panda_joint5" name="j5"/>
        <motor ctrllimited="true" ctrlrange="-12.0 12.0" joint="panda_joint6" name="j6"/>
        <motor ctrllimited="true" ctrlrange="-12.0 12.0" joint="panda_joint7" name="j7"/>
    </actuator>
</mujoco>
